Workbook

Sheet Dordrecth_Finland_600LPF_125Ah
A1: Time (sec) | B1: Load Profile (kW) | C1: Battery power (kW) | D1: Total Batt Power (kW) | E1: Fuel cell power (kW) | F1: Abs(Pfc(t)-Pfc(t-1) | G1: TotalFC power (kW) | H1: Battery SoC (%) | AJ1: Sampling_dt(sec) | AK1: Sampling_dt(hrs) | AL1: Fuel consumption (f(pfc)) for 1 FC (kW) | AM1: Addit_Ploss(kW) | AN1: Fctotal(kw) | AP1: FC_total*hrs(kwh) | AQ1: Ke-m ( kg/kwh) | AR1: Fuel consumption (kg) | AS1: H2 in $/kg | AT1: Fuel cost ($) | AU1: H2 price in $/kwh | AW1: Fuel cost ($)
A2: 0 | B2: 0 | C2: 12.350136 | D2: =C2*$K$3 -> 24.700273 | E2: 0 | F2: 0 | G2: =E2*$J$3 -> 0 | H2: 50 | J2: Nfc | K2: Nbat | AJ2: 300 | AK2: =AJ2/3600 -> 0.083333333 | AL2: =$AE$26*E2^2+$AF$26*E2+$AG$26 -> 0.8595 | AN2: =J3*AL2052+AM2 -> 2242198.5 | AP2: =AN2*AK2 -> 186849.88 | AQ2: 0.03 | AR2: =AP2*AQ2 -> 5605.4963 | AS2: 4 | AT2: =AR2*AS2 -> 22421.985 | AU2: =AS2/33.35 -> 0.11994003 | AW2: =AP2*AU2 -> 22410.78
A3: 300 | B3: 0 | C3: -0.075000176 | D3: =C3*$K$3 -> -0.15000035 | E3: 0.016667063 | F3: =ABS(E3-E2) -> 0.016667063 | G3: =E3*$J$3 -> 0.15000356 | H3: 50.542869 | J3: 9 | K3: 2 | AL3: =$AE$26*E3^2+$AF$26*E3+$AG$26 -> 0.88475741
A4: 600 | B4: 23 | C4: 11.499906 | D4: =C4*$K$3 -> 22.999812 | E4: 2.9795083e-05 | F4: =ABS(E4-E3) -> 0.016637268 | G4: =E4*$J$3 -> 0.00026815575 | H4: 50.098241 | AF4: Fuel consumption | AL4: =$AE$26*E4^2+$AF$26*E4+$AG$26 -> 0.85954515 | AQ4: *Source: Cost-effective control of Roll-on/Roll-off Emission-Free Ships
A5: 900 | B5: 87 | C5: 30.399895 | D5: =C5*$K$3 -> 60.79979 | E5: 2.9110887 | F5: =ABS(E5-E4) -> 2.9110589 | G5: =E5*$J$3 -> 26.199798 | H5: 48.21439 | AL5: =$AE$26*E5^2+$AF$26*E5+$AG$26 -> 5.2956306 | AQ5: CHECK END OF LIFE INCREASE IN kg | AR5: =AR2+25.29%*AR2 -> 7023.1264
A6: 1200 | B6: 128 | C6: 29.913923 | D6: =C6*$K$3 -> 59.827845 | E6: 7.574639 | F6: =ABS(E6-E5) -> 4.6635503 | G6: =E6*$J$3 -> 68.171751 | H6: 45.843224 | K6: DC BUS VOLTAGE | AL6: =$AE$26*E6^2+$AF$26*E6+$AG$26 -> 12.505597 | AQ6: 25.29% increase in kg due to FC degrad
A7: 1500 | B7: 149 | C7: 20.211456 | D7: =C7*$K$3 -> 40.422912 | E7: 12.06406 | F7: =ABS(E7-E6) -> 4.4894211 | G7: =E7*$J$3 -> 108.57654 | H7: 43.915621 | AL7: =$AE$26*E7^2+$AF$26*E7+$AG$26 -> 19.566527
A8: 1800 | B8: 260 | C8: 47.01338 | D8: =C8*$K$3 -> 94.026759 | E8: 18.441271 | F8: =ABS(E8-E7) -> 6.3772107 | G8: =E8*$J$3 -> 165.97144 | H8: 41.163769 | AL8: =$AE$26*E8^2+$AF$26*E8+$AG$26 -> 29.799223
A9: 2100 | B9: 233 | C9: 8.1230848 | D9: =C9*$K$3 -> 16.24617 | E9: 24.083625 | F9: =ABS(E9-E8) -> 5.642354 | G9: =E9*$J$3 -> 216.75262 | H9: 39.150735 | AL9: =$AE$26*E9^2+$AF$26*E9+$AG$26 -> 39.051121
A10: 2400 | B10: 188 | C10: -20.269163 | D10: =C10*$K$3 -> -40.538325 | E10: 25.39302 | F10: =ABS(E10-E9) -> 1.3093955 | G10: =E10*$J$3 -> 228.53718 | H10: 39.7331 | AL10: =$AE$26*E10^2+$AF$26*E10+$AG$26 -> 41.224788
A11: 2700 | B11: 152 | C11: -31.461293 | D11: =C11*$K$3 -> -62.922586 | E11: 23.88016 | F11: =ABS(E11-E10) -> 1.5128602 | G11: =E11*$J$3 -> 214.92144 | H11: 41.785562 | AL11: =$AE$26*E11^2+$AF$26*E11+$AG$26 -> 38.714259
A12: 3000 | B12: 197 | C12: -5.669451 | D12: =C12*$K$3 -> -11.338902 | E12: 23.148587 | F12: =ABS(E12-E11) -> 0.73157307 | G12: =E12*$J$3 -> 208.33728 | H12: 43.129592 | AL12: =$AE$26*E12^2+$AF$26*E12+$AG$26 -> 37.505046
A13: 3300 | B13: 225 | C13: 2.5229465 | D13: =C13*$K$3 -> 5.045893 | E13: 24.439161 | F13: =ABS(E13-E12) -> 1.2905742 | G13: =E13*$J$3 -> 219.95245 | H13: 43.220634 | AL13: =$AE$26*E13^2+$AF$26*E13+$AG$26 -> 39.640339
A14: 3600 | B14: 280 | C14: 16.992358 | D14: =C14*$K$3 -> 33.984715 | E14: 27.33477 | F14: =ABS(E14-E13) -> 2.8956083 | G14: =E14*$J$3 -> 246.01293 | H14: 42.401817 | AL14: =$AE$26*E14^2+$AF$26*E14+$AG$26 -> 44.466657
A15: 3900 | B15: 480 | C15: 60.503773 | D15: =C15*$K$3 -> 121.00755 | E15: 38.359204 | F15: =ABS(E15-E14) -> 11.024434 | G15: =E15*$J$3 -> 345.23283 | H15: 38.615394 | AL15: =$AE$26*E15^2+$AF$26*E15+$AG$26 -> 63.290666
A16: 4200 | B16: 533 | C16: 45.686653 | D16: =C16*$K$3 -> 91.373307 | E16: 49.068807 | F16: =ABS(E16-E15) -> 10.709603 | G16: =E16*$J$3 -> 441.61926 | H16: 34.437971 | AL16: =$AE$26*E16^2+$AF$26*E16+$AG$26 -> 82.257817
A17: 4500 | B17: 600 | C17: 40.767212 | D17: =C17*$K$3 -> 81.534424 | E17: 57.606126 | F17: =ABS(E17-E16) -> 8.5373192 | G17: =E17*$J$3 -> 518.45513 | H17: 31.038085 | AL17: =$AE$26*E17^2+$AF$26*E17+$AG$26 -> 97.858306
A18: 4800 | B18: 818 | C18: 37.5531 | D18: =C18*$K$3 -> 75.1062 | E18: 78.858452 | F18: =ABS(E18-E17) -> 21.252326 | G18: =E18*$J$3 -> 709.72607 | H18: 27.81191 | AL18: =$AE$26*E18^2+$AF$26*E18+$AG$26 -> 138.54478
... A20: 5400 | B20: 331 | C20: -87.033635 | D20: =C20*$K$3 -> -174.06727 | E20: 57.635957 | F20: =ABS(E20-E19) -> 23.874083 | G20: =E20*$J$3 -> 518.72361 | H20: 36.023902 | AL20: =$AE$26*E20^2+$AF$26*E20+$AG$26 -> 97.913564
A21: 5700 | B21: 534 | C21: 18.13439 | D21: =C21*$K$3 -> 36.26878 | E21: 55.302086 | F21: =ABS(E21-E20) -> 2.3338713 | G21: =E21*$J$3 -> 497.71877 | H21: 38.449577 | AE21: Fuel consumption (kW) in y axis | AL21: =$AE$26*E21^2+$AF$26*E21+$AG$26 -> 93.606066
A22: 6000 | B22: 740 | C22: 52.46224 | D22: =C22*$K$3 -> 104.92448 | E22: 67.762013 | F22: =ABS(E22-E21) -> 12.459927 | G22: =E22*$J$3 -> 609.85812 | H22: 34.830477 | AE22: Power output (kW) in x axis | AL22: =$AE$26*E22^2+$AF$26*E22+$AG$26 -> 116.97165
A23: 6300 | B23: 702 | C23: 10.850295 | D23: =C23*$K$3 -> 21.70059 | E23: 75.587186 | F23: =ABS(E23-E22) -> 7.825173 | G23: =E23*$J$3 -> 680.28467 | H23: 32.245681 | AL23: =$AE$26*E23^2+$AF$26*E23+$AG$26 -> 132.11009
A24: 6600 | B24: 706 | C24: -2.5921268 | D24: =C24*$K$3 -> -5.1842537 | E24: 79.018491 | F24: =ABS(E24-E23) -> 3.4313048 | G24: =E24*$J$3 -> 711.16642 | H24: 31.965721 | AL24: =$AE$26*E24^2+$AF$26*E24+$AG$26 -> 138.86118
A25: 6900 | B25: 746 | C25: 3.6389054 | D25: =C25*$K$3 -> 7.2778109 | E25: 82.077928 | F25: =ABS(E25-E24) -> 3.0594377 | G25: =E25*$J$3 -> 738.70136 | H25: 31.90763 | AE25: k1 | AF25: k2 | AG25: k3 | AL25: =$AE$26*E25^2+$AF$26*E25+$AG$26 -> 144.93871
A26: 7200 | B26: 751 | C26: -6.329606 | D26: =C26*$K$3 -> -12.659212 | E26: 84.848666 | F26: =ABS(E26-E25) -> 2.770738 | G26: =E26*$J$3 -> 763.638 | H26: 32.043853 | AE26: 0.00292448 | AF26: 1.51536 | AG26: 0.8595 | AL26: =$AE$26*E26^2+$AF$26*E26+$AG$26 -> 150.48997
A27: 7500 | B27: 719 | C27: -27.097408 | D27: =C27*$K$3 -> -54.194815 | E27: 85.908253 | F27: =ABS(E27-E26) -> 1.0595866 | G27: =E27*$J$3 -> 773.17428 | H27: 33.407719 | AL27: =$AE$26*E27^2+$AF$26*E27+$AG$26 -> 152.62476
A28: 7800 | B28: 704 | C28: -32.358031 | D28: =C28*$K$3 -> -64.716062 | E28: 85.410569 | F28: =ABS(E28-E27) -> 0.49768384 | G28: =E28*$J$3 -> 768.69512 | H28: 35.734524 | AL28: =$AE$26*E28^2+$AF$26*E28+$AG$26 -> 151.62124
A29: 8100 | B29: 699 | C29: -30.255994 | D29: =C29*$K$3 -> -60.511988 | E29: 84.38792 | F29: =ABS(E29-E28) -> 1.0226492 | G29: =E29*$J$3 -> 759.49128 | H29: 38.159576 | AL29: =$AE$26*E29^2+$AF$26*E29+$AG$26 -> 149.56374
A30: 8400 | B30: 729 | C30: -13.526743 | D30: =C30*$K$3 -> -27.053485 | E30: 84.003534 | F30: =ABS(E30-E29) -> 0.38438549 | G30: =E30*$J$3 -> 756.03181 | H30: 39.811969 | AL30: =$AE$26*E30^2+$AF$26*E30+$AG$26 -> 148.79196
A31: 8700 | B31: 728 | C31: -14.655551 | D31: =C31*$K$3 -> -29.311102 | E31: 84.143385 | F31: =ABS(E31-E30) -> 0.13985068 | G31: =E31*$J$3 -> 757.29047 | H31: 40.911039 | AL31: =$AE$26*E31^2+$AF$26*E31+$AG$26 -> 149.07266
A32: 9000 | B32: 724 | C32: -15.914665 | D32: =C32*$K$3 -> -31.829331 | E32: 83.978765 | F32: =ABS(E32-E31) -> 0.16461969 | G32: =E32*$J$3 -> 755.80889 | H32: 42.102622 | AL32: =$AE$26*E32^2+$AF$26*E32+$AG$26 -> 148.74226
A33: 9300 | B33: 735 | C33: -9.9974718 | D33: =C33*$K$3 -> -19.994944 | E33: 83.886003 | F33: =ABS(E33-E32) -> 0.09276232 | G33: =E33*$J$3 -> 754.97403 | H33: 43.09234 | AE33: BATTERY DEGRADATION | AL33: =$AE$26*E33^2+$AF$26*E33+$AG$26 -> 148.55615
A34: 9600 | B34: 735 | C34: -10.17627 | D34: =C34*$K$3 -> -20.352539 | E34: 83.925777 | F34: =ABS(E34-E33) -> 0.039774173 | G34: =E34*$J$3 -> 755.332 | H34: 43.876949 | AL34: =$AE$26*E34^2+$AF$26*E34+$AG$26 -> 148.63595
A35: 9900 | B35: 697 | C35: -25.021821 | D35: =C35*$K$3 -> -50.043643 | E35: 83.002768 | F35: =ABS(E35-E34) -> 0.92300886 | G35: =E35*$J$3 -> 747.02492 | H35: 45.285503 | AL35: =$AE$26*E35^2+$AF$26*E35+$AG$26 -> 146.78666
A36: 10200 | B36: 434 | C36: -86.2468 | D36: =C36*$K$3 -> -172.4936 | E36: 70.099664 | F36: =ABS(E36-E35) -> 12.903105 | G36: =E36*$J$3 -> 630.89697 | H36: 50.653144 | AL36: =$AE$26*E36^2+$AF$26*E36+$AG$26 -> 121.45651
A37: 10500 | B37: 440 | C37: -49.326334 | D37: =C37*$K$3 -> -98.652669 | E37: 59.849165 | F37: =ABS(E37-E36) -> 10.250499 | G37: =E37*$J$3 -> 538.64248 | H37: 55.854063 | AL37: =$AE$26*E37^2+$AF$26*E37+$AG$26 -> 102.02779
A38: 10800 | B38: 330 | C38: -64.936392 | D38: =C38*$K$3 -> -129.87278 | E38: 51.297716 | F38: =ABS(E38-E37) -> 8.5514485 | G38: =E38*$J$3 -> 461.67945 | H38: 60.362663 | AL38: =$AE$26*E38^2+$AF$26*E38+$AG$26 -> 86.289647
A39: 11100 | B39: 305 | C39: -39.117809 | D39: =C39*$K$3 -> -78.235619 | E39: 42.581226 | F39: =ABS(E39-E38) -> 8.7164905 | G39: =E39*$J$3 -> 383.23103 | H39: 64.305418 | AL39: =$AE$26*E39^2+$AF$26*E39+$AG$26 -> 70.687939
A40: 11400 | B40: 252 | C40: -31.421228 | D40: =C40*$K$3 -> -62.842455 | E40: 34.982202 | F40: =ABS(E40-E39) -> 7.5990235 | G40: =E40*$J$3 -> 314.83982 | H40: 66.997868 | AL40: =$AE$26*E40^2+$AF$26*E40+$AG$26 -> 57.448976
A41: 11700 | B41: 464 | C41: 74.712722 | D41: =C41*$K$3 -> 149.42544 | E41: 34.952074 | F41: =ABS(E41-E40) -> 0.030128188 | G41: =E41*$J$3 -> 314.56867 | H41: 64.896746 | AL41: =$AE$26*E41^2+$AF$26*E41+$AG$26 -> 57.397159
...

Sheet Finland_ports_600LPF_125Ah
A1: Time (sec) | B1: Load Profile (kW) | C1: Battery power (kW) | D1: Total Batt Power (kW) | E1: FC power (kW) | F1: Abs(Pfc(t)-Pfc(t-1) | G1: TotalFC power(kw) | H1: Battery SoC (%) | AK1: Sampling_dt(sec) | AL1: Sampling_dt(hrs) | AM1: Fuel consumption (f(pfc)) for 1 FC (kW) | AN1: Addit_Ploss(kW) | AO1: Fctotal(kw) | AQ1: FC_total*hrs(kwh) | AR1: Ke-m ( kg/kwh) | AS1: Fuel consumption (kg) | AU1: H2 in $/kg | AV1: Fuel cost | AW1: H2 price in $/kwh | AY1: Fuel cost ($)
A2: 0 | B2: 0 | C2: 12.350136 | D2: =$K$3*C2 -> 24.700273 | E2: 0 | F2: 0 | G2: =$J$3*E2 -> 0 | H2: 50 | J2: Nfc | K2: Nbat | AK2: 300 | AL2: =AK2/3600 -> 0.083333333 | AM2: =$AF$26*E2^2+$AG$26*E2+$AH$26 -> 0.8595 | AO2: =J3*AM103+AN2 -> 95615.187 | AQ2: =AO2*AL2 -> 7967.9323 | AR2: 0.03 | AS2: =AQ2*AR2 -> 239.03797 | AU2: 4 | AV2: =AU2*AS2 -> 956.15187 | AW2: =AU2/33.35 -> 0.11994003 | AY2: =AQ2*AW2 -> 955.67403
A3: 300 | B3: 0 | C3: -0.075000176 | D3: =$K$3*C3 -> -0.15000035 | E3: 0.016667063 | F3: =ABS(E3-E2) -> 0.016667063 | G3: =$J$3*E3 -> 0.15000356 | H3: 50.542869 | J3: 9 | K3: 2 | AM3: =$AF$26*E3^2+$AG$26*E3+$AH$26 -> 0.88475741
A4: 600 | B4: 24 | C4: 11.999908 | D4: =$K$3*C4 -> 23.999816 | E4: 2.981693e-05 | F4: =ABS(E4-E3) -> 0.016637246 | G4: =$J$3*E4 -> 0.00026835237 | H4: 50.078835 | AG4: Fuel consumption | AM4: =$AF$26*E4^2+$AG$26*E4+$AH$26 -> 0.85954518 | AR4: *Source: Cost-effective control of Roll-on/Roll-off Emission-Free Ships
A5: 900 | B5: 85 | C5: 29.276072 | D5: =$K$3*C5 -> 58.552144 | E5: 2.9386053 | F5: =ABS(E5-E4) -> 2.9385754 | G5: =$J$3*E5 -> 26.447447 | H5: 48.21991 | AM5: =$AF$26*E5^2+$AG$26*E5+$AH$26 -> 5.3377989 | AR5: CHECK END OF LIFE INCREASE IN kg | AS5: =AS2+25.29%*AS2 -> 299.49067
A6: 1200 | B6: 116 | C6: 25.761904 | D6: =$K$3*C6 -> 51.523809 | E6: 7.1639838 | F6: =ABS(E6-E5) -> 4.2253785 | G6: =$J$3*E6 -> 64.475854 | H6: 46.062143 | K6: DC BUS VOLTAGE | AM6: =$AF$26*E6^2+$AG$26*E6+$AH$26 -> 11.865607 | AR6: 25.29% increase in kg due to FC degrad
A7: 1500 | B7: 108 | C7: 7.5599843 | D7: =$K$3*C7 -> 15.119969 | E7: 10.31997 | F7: =ABS(E7-E6) -> 3.1559862 | G7: =$J$3*E7 -> 92.87973 | H7: 44.829347 | AM7: =$AF$26*E7^2+$AG$26*E7+$AH$26 -> 16.809432
A8: 1800 | B8: 105 | C8: -0.95221036 | D8: =$K$3*C8 -> -1.9044207 | E8: 11.878231 | F8: =ABS(E8-E7) -> 1.5582608 | G8: =$J$3*E8 -> 106.90408 | H8: 44.605025 | AM8: =$AF$26*E8^2+$AG$26*E8+$AH$26 -> 19.271918
A9: 2100 | B9: 117 | C9: 0.0091042133 | D9: =$K$3*C9 -> 0.018208427 | E9: 12.997927 | F9: =ABS(E9-E8) -> 1.119696 | G9: =$J$3*E9 -> 116.98134 | H9: 44.638001 | AM9: =$AF$26*E9^2+$AG$26*E9+$AH$26 -> 21.050118
A10: 2400 | B10: 219 | C10: 33.772294 | D10: =$K$3*C10 -> 67.544588 | E10: 16.828229 | F10: =ABS(E10-E9) -> 3.8303022 | G10: =$J$3*E10 -> 151.45406 | H10: 43.179598 | AM10: =$AF$26*E10^2+$AG$26*E10+$AH$26 -> 27.188507
A11: 2700 | B11: 283 | C11: 36.355104 | D11: =$K$3*C11 -> 72.710208 | E11: 23.365304 | F11: =ABS(E11-E10) -> 6.5370749 | G11: =$J$3*E11 -> 210.28774 | H11: 40.411896 | AM11: =$AF$26*E11^2+$AG$26*E11+$AH$26 -> 37.86293
A12: 3000 | B12: 221 | C12: -10.865427 | D12: =$K$3*C12 -> -21.730855 | E12: 26.969969 | F12: =ABS(E12-E11) -> 3.6046655 | G12: =$J$3*E12 -> 242.72973 | H12: 39.594992 | AM12: =$AF$26*E12^2+$AG$26*E12+$AH$26 -> 43.855919
A13: 3300 | B13: 209 | C13: -17.641434 | D13: =$K$3*C13 -> -35.282869 | E13: 27.142357 | F13: =ABS(E13-E12) -> 0.17238754 | G13: =$J$3*E13 -> 244.28121 | H13: 40.730939 | AM13: =$AF$26*E13^2+$AG$26*E13+$AH$26 -> 44.144429
A14: 3600 | B14: 134 | C14: -43.968403 | D14: =$K$3*C14 -> -87.936806 | E14: 24.659534 | F14: =ABS(E14-E13) -> 2.4828228 | G14: =$J$3*E14 -> 221.93581 | H14: 43.220176 | AM14: =$AF$26*E14^2+$AG$26*E14+$AH$26 -> 40.005927
A15: 3900 | B15: 152 | C15: -21.292454 | D15: =$K$3*C15 -> -42.584909 | E15: 21.620402 | F15: =ABS(E15-E14) -> 3.0391325 | G15: =$J$3*E15 -> 194.58362 | H15: 45.662993 | AM15: =$AF$26*E15^2+$AG$26*E15+$AH$26 -> 34.989216
A16: 4200 | B16: 227 | C16: 13.60631 | D16: =$K$3*C16 -> 27.212621 | E16: 22.198406 | F16: =ABS(E16-E15) -> 0.57800385 | G16: =$J$3*E16 -> 199.78565 | H16: 45.825347 | AM16: =$AF$26*E16^2+$AG$26*E16+$AH$26 -> 35.93917
A17: 4500 | B17: 226 | C17: 3.7630417 | D17: =$K$3*C17 -> 7.5260833 | E17: 24.274724 | F17: =ABS(E17-E16) -> 2.076318 | G17: =$J$3*E17 -> 218.47251 | H17: 45.18557 | AM17: =$AF$26*E17^2+$AG$26*E17+$AH$26 -> 39.367731
A18: 4800 | B18: 211 | C18: -7.0602508 | D18: =$K$3*C18 -> -14.120502 | E18: 25.013237 | F18: =ABS(E18-E17) -> 0.73851385 | G18: =$J$3*E18 -> 225.11914 | H18: 45.355631 | AM18: =$AF$26*E18^2+$AG$26*E18+$AH$26 -> 40.593296
... A20: 5400 | B20: 226 | C20: 1.3943771 | D20: =$K$3*C20 -> 2.7887543 | E20: 24.801061 | F20: =ABS(E20-E19) -> 0.15864867 | G20: =$J$3*E20 -> 223.20955 | H20: 46.468697 | AM20: =$AF$26*E20^2+$AG$26*E20+$AH$26 -> 40.240861
A21: 5700 | B21: 229 | C21: -0.67352585 | D21: =$K$3*C21 -> -1.3470517 | E21: 25.59394 | F21: =ABS(E21-E20) -> 0.79287967 | G21: =$J$3*E21 -> 230.34546 | H21: 46.448602 | AF21: Fuel consumption (kW) in y axis | AM21: =$AF$26*E21^2+$AG$26*E21+$AH$26 -> 41.559213
A22: 6000 | B22: 221 | C22: -5.8787648 | D22: =$K$3*C22 -> -11.75753 | E22: 25.861778 | F22: =ABS(E22-E21) -> 0.26783771 | G22: =$J$3*E22 -> 232.756 | H22: 46.723653 | AF22: Power output (kW) in x axis | AM22: =$AF$26*E22^2+$AG$26*E22+$AH$26 -> 42.005388
A23: 6300 | B23: 207 | C23: -10.667456 | D23: =$K$3*C23 -> -21.334912 | E23: 25.370387 | F23: =ABS(E23-E22) -> 0.49139071 | G23: =$J$3*E23 -> 228.33349 | H23: 47.38548 | AM23: =$AF$26*E23^2+$AG$26*E23+$AH$26 -> 41.187131
A24: 6600 | B24: 220 | C24: -2.6422705 | D24: =$K$3*C24 -> -5.284541 | E24: 25.031437 | F24: =ABS(E24-E23) -> 0.33895 | G24: =$J$3*E24 -> 225.28294 | H24: 47.872401 | AM24: =$AF$26*E24^2+$AG$26*E24+$AH$26 -> 40.623538
A25: 6900 | B25: 220 | C25: -2.9140526 | D25: =$K$3*C25 -> -5.8281052 | E25: 25.091845 | F25: =ABS(E25-E24) -> 0.060407417 | G25: =$J$3*E25 -> 225.8266 | H25: 48.089713 | AF25: k1 | AG25: k2 | AH25: k3 | AM25: =$AF$26*E25^2+$AG$26*E25+$AH$26 -> 40.723932
A26: 7200 | B26: 215 | C26: -4.7665969 | D26: =$K$3*C26 -> -9.5331938 | E26: 24.947972 | F26: =ABS(E26-E25) -> 0.14387264 | G26: =$J$3*E26 -> 224.53175 | H26: 48.395699 | AF26: 0.00292448 | AG26: 1.51536 | AH26: 0.8595 | AM26: =$AF$26*E26^2+$AG$26*E26+$AH$26 -> 40.484859
A27: 7500 | B27: 174 | C27: -18.945865 | D27: =$K$3*C27 -> -37.89173 | E27: 23.54341 | F27: =ABS(E27-E26) -> 1.4045622 | G27: =$J$3*E27 -> 211.89069 | H27: 49.370929 | AM27: =$AF$26*E27^2+$AG$26*E27+$AH$26 -> 38.157258
A28: 7800 | B28: 120 | C28: -30.496477 | D28: =$K$3*C28 -> -60.992953 | E28: 20.110246 | F28: =ABS(E28-E27) -> 3.4331639 | G28: =$J$3*E28 -> 180.99221 | H28: 51.330724 | AM28: =$AF$26*E28^2+$AG$26*E28+$AH$26 -> 32.516486
A29: 8100 | B29: 198 | C29: 13.978826 | D29: =$K$3*C29 -> 27.957651 | E29: 18.893452 | F29: =ABS(E29-E28) -> 1.2167941 | G29: =$J$3*E29 -> 170.04107 | H29: 51.797126 | AM29: =$AF$26*E29^2+$AG$26*E29+$AH$26 -> 30.533811
A30: 8400 | B30: 366 | C30: 70.870628 | D30: =$K$3*C30 -> 141.74126 | E30: 24.917255 | F30: =ABS(E30-E29) -> 6.023803 | G30: =$J$3*E30 -> 224.25529 | H30: 48.233346 | AM30: =$AF$26*E30^2+$AG$26*E30+$AH$26 -> 40.433832
A31: 8700 | B31: 667 | C31: 68.490711 | D31: =$K$3*C31 -> 136.98142 | E31: 55.022321 | F31: =ABS(E31-E30) -> 30.105066 | G31: =$J$3*E31 -> 495.20089 | H31: 42.39004 | AM31: =$AF$26*E31^2+$AG$26*E31+$AH$26 -> 93.091858
A32: 9000 | B32: 864 | C32: 57.944805 | D32: =$K$3*C32 -> 115.88961 | E32: 79.652226 | F32: =ABS(E32-E31) -> 24.629905 | G32: =$J$3*E32 -> 716.87003 | H32: 37.418592 | AF32: BATTERY DEGRADATION | AM32: =$AF$26*E32^2+$AG$26*E32+$AH$26 -> 140.11559
A33: 9300 | B33: 847 | C33: 26.563231 | D33: =$K$3*C33 -> 53.126462 | E33: 88.20565 | F33: =ABS(E33-E32) -> 8.5534242 | G33: =$J$3*E33 -> 793.85085 | H33: 33.947226 | AM33: =$AF$26*E33^2+$AG$26*E33+$AH$26 -> 157.27596
A34: 9600 | B34: 836 | C34: 3.1795292 | D34: =$K$3*C34 -> 6.3590584 | E34: 92.179501 | F34: =ABS(E34-E33) -> 3.9738502 | G34: =$J$3*E34 -> 829.6155 | H34: 32.849093 | AE34: DoD = maxSoC - minSoC = | AG34: 40.6059 | AM34: =$AF$26*E34^2+$AG$26*E34+$AH$26 -> 165.39411
A35: 9900 | B35: 787 | C35: -27.325184 | D35: =$K$3*C35 -> -54.650368 | E35: 93.513948 | F35: =ABS(E35-E34) -> 1.3344478 | G35: =$J$3*E35 -> 841.62554 | H35: 33.87432 | AM35: =$AF$26*E35^2+$AG$26*E35+$AH$26 -> 168.14096
A36: 10200 | B36: 837 | C36: -5.9672112 | D36: =$K$3*C36 -> -11.934422 | E36: 94.32277 | F36: =ABS(E36-E35) -> 0.80882197 | G36: =$J$3*E36 -> 848.90493 | H36: 35.113299 | AM36: =$AF$26*E36^2+$AG$26*E36+$AH$26 -> 169.81092
A37: 10500 | B37: 843 | C37: -9.4919618 | D37: =$K$3*C37 -> -18.983924 | E37: 95.772795 | F37: =ABS(E37-E36) -> 1.4500249 | G37: =$J$3*E37 -> 861.95516 | H37: 35.726143 | AM37: =$AF$26*E37^2+$AG$26*E37+$AH$26 -> 172.81435
A38: 10800 | B38: 840 | C38: -15.043842 | D38: =$K$3*C38 -> -30.087684 | E38: 96.673177 | F38: =ABS(E38-E37) -> 0.90038202 | G38: =$J$3*E38 -> 870.0586 | H38: 36.696879 | AM38: =$AF$26*E38^2+$AG$26*E38+$AH$26 -> 174.68549
A39: 11100 | B39: 857 | C39: -9.9178047 | D39: =$K$3*C39 -> -19.835609 | E39: 97.422786 | F39: =ABS(E39-E38) -> 0.74960881 | G39: =$J$3*E39 -> 876.80507 | H39: 37.655322 | AM39: =$AF$26*E39^2+$AG$26*E39+$AH$26 -> 176.24692
A40: 11400 | B40: 867 | C40: -8.941699 | D40: =$K$3*C40 -> -17.883398 | E40: 98.316938 | F40: =ABS(E40-E39) -> 0.89415231 | G40: =$J$3*E40 -> 884.85245 | H40: 38.387015 | AM40: =$AF$26*E40^2+$AG$26*E40+$AH$26 -> 178.11372
A41: 11700 | B41: 852 | C41: -18.130676 | D41: =$K$3*C41 -> -36.261351 | E41: 98.692352 | F41: =ABS(E41-E40) -> 0.37541332 | G41: =$J$3*E41 -> 888.23117 | H41: 39.464028 | AM41: =$AF$26*E41^2+$AG$26*E41+$AH$26 -> 178.8989
...

Sheet Finland_SSweden_600LPF_125Ah
A1: Time (sec) | B1: Load Profile (kW) | C1: Battery power (kW) | D1: Total Batt Power (kW) | E1: FC power (kW) | F1: Abs(Pfc(t)-Pfc(t-1) | G1: TotalFC power(kw) | H1: Battery SoC (%) | AK1: Sampling_dt(sec) | AL1: Sampling_dt(hrs) | AM1: Fuel consumption (f(pfc)) for 1 FC (kW) | AN1: Addit_Ploss(kW) | AO1: Fctotal(kw) | AQ1: FC_total*hrs(kwh) | AR1: Ke-m ( kg/kwh) | AS1: Fuel consumption (kg) | AU1: H2 in $/kg | AV1: Fuel cost | AW1: H2 price in $/kwh | AY1: Fuel cost ($)
A2: 0 | B2: 0 | C2: 12.350136 | D2: =$K$3*C2 -> 24.700273 | E2: 0 | F2: 0 | G2: =$J$3*E2 -> 0 | H2: 50 | J2: Nfc | K2: Nbat | AK2: 300 | AL2: =AK2/3600 -> 0.083333333 | AM2: =$AF$28*E2^2+$AG$28*E2+$AH$28 -> 0.8595 | AO2: =J3*AM864+AN2 -> 896545.62 | AQ2: =AO2*AL2 -> 74712.135 | AR2: 0.03 | AS2: =AQ2*AR2 -> 2241.364 | AU2: 4 | AV2: =AU2*AS2 -> 8965.4562 | AW2: =AU2/33.35 -> 0.11994003 | AY2: =AQ2*AW2 -> 8960.9757
A3: 300 | B3: 0 | C3: -0.075000176 | D3: =$K$3*C3 -> -0.15000035 | E3: 0.016667063 | F3: =ABS(E3-E2) -> 0.016667063 | G3: =$J$3*E3 -> 0.15000356 | H3: 50.542869 | J3: 9 | K3: 2 | AM3: =$AF$28*E3^2+$AG$28*E3+$AH$28 -> 0.88475741
A4: 600 | B4: 19 | C4: 9.4998992 | D4: =$K$3*C4 -> 18.999798 | E4: 2.9708356e-05 | F4: =ABS(E4-E3) -> 0.016637354 | G4: =$J$3*E4 -> 0.00026737521 | H4: 50.175835 | AM4: =$AF$28*E4^2+$AG$28*E4+$AH$28 -> 0.85954502 | AR4: *Source: Cost-effective control of Roll-on/Roll-off Emission-Free Ships
A5: 900 | B5: 50 | C5: 19.278393 | D5: =$K$3*C5 -> 38.556786 | E5: 1.2714488 | F5: =ABS(E5-E4) -> 1.2714191 | G5: =$J$3*E5 -> 11.443039 | H5: 48.913984 | AM5: =$AF$28*E5^2+$AG$28*E5+$AH$28 -> 2.7909303 | AR5: CHECK END OF LIFE INCREASE IN kg | AS5: =AS2+25.29%*AS2 -> 2808.205
A6: 1200 | B6: 110 | C6: 30.7094 | D6: =$K$3*C6 -> 61.418799 | E6: 5.3978812 | F6: =ABS(E6-E5) -> 4.1264324 | G6: =$J$3*E6 -> 48.580931 | H6: 46.961022 | K6: DC BUS VOLTAGE | AG6: Fuel consumption | AM6: =$AF$28*E6^2+$AG$28*E6+$AH$28 -> 9.1244442 | AR6: 25.29% increase in kg due to FC degrad
A7: 1500 | B7: 124 | C7: 18.936018 | D7: =$K$3*C7 -> 37.872037 | E7: 9.5697314 | F7: =ABS(E7-E6) -> 4.1718502 | G7: =$J$3*E7 -> 86.127582 | H7: 45.059608 | AM7: =$AF$28*E7^2+$AG$28*E7+$AH$28 -> 15.628911
A8: 1800 | B8: 118 | C8: 4.0007855 | D8: =$K$3*C8 -> 8.001571 | E8: 12.222006 | F8: =ABS(E8-E7) -> 2.6522745 | G8: =$J$3*E8 -> 109.99805 | H8: 44.221846 | AM8: =$AF$28*E8^2+$AG$28*E8+$AH$28 -> 19.81709
A9: 2100 | B9: 112 | C9: -4.3442259 | D9: =$K$3*C9 -> -8.6884518 | E9: 13.409782 | F9: =ABS(E9-E8) -> 1.1877762 | G9: =$J$3*E9 -> 120.68804 | H9: 44.268078 | AM9: =$AF$28*E9^2+$AG$28*E9+$AH$28 -> 21.706034
A10: 2400 | B10: 112 | C10: -6.4206418 | D10: =$K$3*C10 -> -12.841284 | E10: 13.871203 | F10: =ABS(E10-E9) -> 0.46142079 | G10: =$J$3*E10 -> 124.84083 | H10: 44.695548 | AM10: =$AF$28*E10^2+$AG$28*E10+$AH$28 -> 22.442066
A11: 2700 | B11: 112 | C11: -7.1872123 | D11: =$K$3*C11 -> -14.374425 | E11: 14.041551 | F11: =ABS(E11-E10) -> 0.17034784 | G11: =$J$3*E11 -> 126.37396 | H11: 45.228388 | AM11: =$AF$28*E11^2+$AG$28*E11+$AH$28 -> 22.71411
A12: 3000 | B12: 112 | C12: -7.1977536 | D12: =$K$3*C12 -> -14.395507 | E12: 14.043893 | F12: =ABS(E12-E11) -> 0.0023425354 | G12: =$J$3*E12 -> 126.39504 | H12: 45.788375 | AM12: =$AF$28*E12^2+$AG$28*E12+$AH$28 -> 22.717852
A13: 3300 | B13: 111 | C13: -7.1656627 | D13: =$K$3*C13 -> -14.331325 | E13: 13.925652 | F13: =ABS(E13-E12) -> 0.11824105 | G13: =$J$3*E13 -> 125.33087 | H13: 46.347261 | AM13: =$AF$28*E13^2+$AG$28*E13+$AH$28 -> 22.529002
A14: 3600 | B14: 124 | C14: -1.5700237 | D14: =$K$3*C14 -> -3.1400473 | E14: 14.126614 | F14: =ABS(E14-E13) -> 0.20096187 | G14: =$J$3*E14 -> 127.13953 | H14: 46.66532 | AM14: =$AF$28*E14^2+$AG$28*E14+$AH$28 -> 22.850019
A15: 3900 | B15: 235 | C15: 37.776748 | D15: =$K$3*C15 -> 75.553497 | E15: 17.716109 | F15: =ABS(E15-E14) -> 3.5894952 | G15: =$J$3*E15 -> 159.44498 | H15: 45.089904 | AM15: =$AF$28*E15^2+$AG$28*E15+$AH$28 -> 28.623662
A16: 4200 | B16: 428 | C16: 64.188244 | D16: =$K$3*C16 -> 128.37649 | E16: 32.040253 | F16: =ABS(E16-E15) -> 14.324143 | G16: =$J$3*E16 -> 288.36227 | H16: 40.366277 | AM16: =$AF$28*E16^2+$AG$28*E16+$AH$28 -> 52.414223
A17: 4500 | B17: 742 | C17: 54.307327 | D17: =$K$3*C17 -> 108.61465 | E17: 65.601597 | F17: =ABS(E17-E16) -> 33.561344 | G17: =$J$3*E17 -> 590.41437 | H17: 35.702684 | AM17: =$AF$28*E17^2+$AG$28*E17+$AH$28 -> 112.85524
A18: 4800 | B18: 926 | C18: 45.930223 | D18: =$K$3*C18 -> 91.860447 | E18: 89.004652 | F18: =ABS(E18-E17) -> 23.403056 | G18: =$J$3*E18 -> 801.04187 | H18: 31.758282 | AM18: =$AF$28*E18^2+$AG$28*E18+$AH$28 -> 158.90082
A19: 5100 | B19: 916 | C19: 20.637062 | D19: =$K$3*C19 -> 41.274124 | E19: 97.188501 | F19: =ABS(E19-E18) -> 8.1838491 | G19: =$J$3*E19 -> 874.69651 | H19: 28.972678 | S19: WE SHOULD SAY THAT THE AS ANDREA SAID..FOR EACH PROFILE | AM19: =$AF$28*E19^2+$AG$28*E19+$AH$28 -> 175.75855
A20: 5400 | B20: 905 | C20: -2.3926231 | D20: =$K$3*C20 -> -4.7852461 | E20: 101.08366 | F20: =ABS(E20-E19) -> 3.8951571 | G20: =$J$3*E20 -> 909.75293 | H20: 28.319208 | S20: WE GET 1 DESIGN…....Pbatmax from the profiles based on the operation of FC it covers the differnece… | AM20: =$AF$28*E20^2+$AG$28*E20+$AH$28 -> 183.91969
A21: 5700 | B21: 738 | C21: -81.496515 | D21: =$K$3*C21 -> -162.99303 | E21: 100.10755 | F21: =ABS(E21-E20) -> 0.97610911 | G21: =$J$3*E21 -> 900.96794 | H21: 31.776453 | S21: Pbat max = Ebatmax/Crate ….assume C-rate = 1… | AM21: =$AF$28*E21^2+$AG$28*E21+$AH$28 -> 181.86621
A22: 6000 | B22: 695 | C22: -80.13257 | D22: =$K$3*C22 -> -160.26514 | E22: 95.026471 | F22: =ABS(E22-E21) -> 5.0810782 | G22: =$J$3*E22 -> 855.23824 | H22: 38.003005 | S22: we should say this as a way to size the batteries. | AM22: =$AF$28*E22^2+$AG$28*E22+$AH$28 -> 171.26696
A23: 6300 | B23: 687 | C23: -60.888276 | D23: =$K$3*C23 -> -121.77655 | E23: 89.861339 | F23: =ABS(E23-E22) -> 5.1651317 | G23: =$J$3*E23 -> 808.75205 | H23: 43.38354 | AF23: Fuel consumption (kW) in y axis | AM23: =$AF$28*E23^2+$AG$28*E23+$AH$28 -> 160.64713
A24: 6600 | B24: 663 | C24: -51.504457 | D24: =$K$3*C24 -> -103.00891 | E24: 85.109789 | F24: =ABS(E24-E23) -> 4.7515499 | G24: =$J$3*E24 -> 765.9881 | H24: 47.689404 | AF24: Power output (kW) in x axis | AM24: =$AF$28*E24^2+$AG$28*E24+$AH$28 -> 151.01546
A25: 6900 | B25: 655 | C25: -36.244655 | D25: =$K$3*C25 -> -72.48931 | E25: 80.83006 | F25: =ABS(E25-E24) -> 4.2797298 | G25: =$J$3*E25 -> 727.47054 | H25: 51.031212 | AM25: =$AF$28*E25^2+$AG$28*E25+$AH$28 -> 142.45322
A26: 7200 | B26: 677 | C26: -12.654784 | D26: =$K$3*C26 -> -25.309568 | E26: 78.032389 | F26: =ABS(E26-E25) -> 2.7976708 | G26: =$J$3*E26 -> 702.2915 | H26: 52.85283 | AM26: =$AF$28*E26^2+$AG$28*E26+$AH$28 -> 136.91398
A27: 7500 | B27: 662 | C27: -11.838963 | D27: =$K$3*C27 -> -23.677926 | E27: 76.18467 | F27: =ABS(E27-E26) -> 1.8477188 | G27: =$J$3*E27 -> 685.66203 | H27: 53.799889 | AF27: k1 | AG27: k2 | AH27: k3 | AM27: =$AF$28*E27^2+$AG$28*E27+$AH$28 -> 133.28069
A28: 7800 | B28: 651 | C28: -9.12053 | D28: =$K$3*C28 -> -18.24106 | E28: 74.358437 | F28: =ABS(E28-E27) -> 1.8262327 | G28: =$J$3*E28 -> 669.22593 | H28: 54.604404 | AF28: 0.00292448 | AG28: 1.51536 | AH28: 0.8595 | AM28: =$AF$28*E28^2+$AG$28*E28+$AH$28 -> 129.70927
A29: 8100 | B29: 650 | C29: -3.0004208 | D29: =$K$3*C29 -> -6.0008415 | E29: 72.887348 | F29: =ABS(E29-E28) -> 1.4710894 | G29: =$J$3*E29 -> 655.98613 | H29: 55.055876 | AM29: =$AF$28*E29^2+$AG$28*E29+$AH$28 -> 126.84656
A30: 8400 | B30: 647 | C30: 0.16050925 | D30: =$K$3*C30 -> 0.32101851 | E30: 71.851647 | F30: =ABS(E30-E29) -> 1.0357008 | G30: =$J$3*E30 -> 646.66482 | H30: 55.156372 | AM30: =$AF$28*E30^2+$AG$28*E30+$AH$28 -> 124.83871
A31: 8700 | B31: 649 | C31: 4.0735405 | D31: =$K$3*C31 -> 8.147081 | E31: 71.204324 | F31: =ABS(E31-E30) -> 0.64732291 | G31: =$J$3*E31 -> 640.83892 | H31: 54.97957 | AM31: =$AF$28*E31^2+$AG$28*E31+$AH$28 -> 123.58696
A32: 9000 | B32: 653 | C32: 7.0638713 | D32: =$K$3*C32 -> 14.127743 | E32: 70.984256 | F32: =ABS(E32-E31) -> 0.22006825 | G32: =$J$3*E32 -> 638.8583 | H32: 54.537029 | AM32: =$AF$28*E32^2+$AG$28*E32+$AH$28 -> 123.16197
A33: 9300 | B33: 651 | C33: 6.1987068 | D33: =$K$3*C33 -> 12.397414 | E33: 70.954314 | F33: =ABS(E33-E32) -> 0.029942006 | G33: =$J$3*E33 -> 638.58883 | H33: 54.023921 | AM33: =$AF$28*E33^2+$AG$28*E33+$AH$28 -> 123.10417
A34: 9600 | B34: 650 | C34: 5.7620129 | D34: =$K$3*C34 -> 11.524026 | E34: 70.940243 | F34: =ABS(E34-E33) -> 0.014070421 | G34: =$J$3*E34 -> 638.46219 | H34: 53.560113 | AF34: BATTERY DEGRADATION | AM34: =$AF$28*E34^2+$AG$28*E34+$AH$28 -> 123.07701
A35: 9900 | B35: 650 | C35: 5.6089445 | D35: =$K$3*C35 -> 11.217889 | E35: 70.974254 | F35: =ABS(E35-E34) -> 0.034010286 | G35: =$J$3*E35 -> 638.76828 | H35: 53.11832 | AM35: =$AF$28*E35^2+$AG$28*E35+$AH$28 -> 123.14266
A36: 10200 | B36: 647 | C36: 4.0672287 | D36: =$K$3*C36 -> 8.1344574 | E36: 70.983533 | F36: =ABS(E36-E35) -> 0.0092795206 | G36: =$J$3*E36 -> 638.8518 | H36: 52.746876 | AE36: DoD | AF36: 35.6 | AM36: =$AF$28*E36^2+$AG$28*E36+$AH$28 -> 123.16057
A37: 10500 | B37: 647 | C37: 4.1044455 | D37: =$K$3*C37 -> 8.208891 | E37: 70.975253 | F37: =ABS(E37-E36) -> 0.0082798408 | G37: =$J$3*E37 -> 638.77728 | H37: 52.428969 | AM37: =$AF$28*E37^2+$AG$28*E37+$AH$28 -> 123.14459
A38: 10800 | B38: 650 | C38: 5.1065724 | D38: =$K$3*C38 -> 10.213145 | E38: 71.085877 | F38: =ABS(E38-E37) -> 0.11062326 | G38: =$J$3*E38 -> 639.77289 | H38: 52.067506 | AM38: =$AF$28*E38^2+$AG$28*E38+$AH$28 -> 123.35818
A39: 11100 | B39: 650 | C39: 4.2967102 | D39: =$K$3*C39 -> 8.5934204 | E39: 71.265847 | F39: =ABS(E39-E38) -> 0.17997034 | G39: =$J$3*E39 -> 641.39262 | H39: 51.704271 | AM39: =$AF$28*E39^2+$AG$28*E39+$AH$28 -> 123.70582
A40: 11400 | B40: 647 | C40: 2.4159221 | D40: =$K$3*C40 -> 4.8318443 | E40: 71.350472 | F40: =ABS(E40-E39) -> 0.08462505 | G40: =$J$3*E40 -> 642.15425 | H40: 51.449145 | AM40: =$AF$28*E40^2+$AG$28*E40+$AH$28 -> 123.86936
...

Sheet sSweden_Nether_600LPF_125Ah
A1: Time (sec) | B1: Load Profile (kW) | C1: Battery power (kW) | D1: Total Batt Power (kW) | E1: FC power (kW) | F1: Abs(Pfc(t)-Pfc(t-1) | G1: TotalFC power(kw) | H1: Battery SoC (%) | AK1: Sampling_dt(sec) | AL1: Sampling_dt(hrs) | AM1: Fuel consumption (f(pfc)) for 1 FC (kW) | AN1: Addit_Ploss(kW) | AO1: Fctotal(kw) | AQ1: FC_total*hrs(kwh) | AR1: Ke-m ( kg/kwh) | AS1: Fuel consumption (kg) | AU1: H2 in $/kg | AV1: Fuel cost | AW1: H2 price in $/kwh | AY1: Fuel cost ($)
A2: 0 | B2: 0 | C2: 12.350136 | D2: =$K$3*C2 -> 24.700273 | E2: 0 | F2: 0 | G2: =$J$3*E2 -> 0 | H2: 50 | J2: Nfc | K2: Nbat | AK2: 300 | AL2: =AK2/3600 -> 0.083333333 | AM2: =$AF$26*E2^2+$AG$26*E2+$AH$26 -> 0.8595 | AO2: =J3*AM1195+AN2 -> 1391281.8 | AQ2: =AO2*AL2 -> 115940.15 | AR2: 0.03 | AS2: =AQ2*AR2 -> 3478.2045 | AU2: 4 | AV2: =AU2*AS2 -> 13912.818 | AW2: =AU2/33.35 -> 0.11994003 | AY2: =AQ2*AW2 -> 13905.865
A3: 300 | B3: 0 | C3: -0.075000176 | D3: =$K$3*C3 -> -0.15000035 | E3: 0.016667063 | F3: =ABS(E3-E2) -> 0.016667063 | G3: =$J$3*E3 -> 0.15000356 | H3: 50.542869 | J3: 9 | K3: 2 | AM3: =$AF$26*E3^2+$AG$26*E3+$AH$26 -> 0.88475741
A4: 600 | B4: 28 | C4: 13.999915 | D4: =$K$3*C4 -> 27.99983 | E4: 2.9905002e-05 | F4: =ABS(E4-E3) -> 0.016637158 | G4: =$J$3*E4 -> 0.00026914502 | H4: 50.001184 | AG4: Fuel consumption | AM4: =$AF$26*E4^2+$AG$26*E4+$AH$26 -> 0.85954532 | AR4: *Source: Cost-effective control of Roll-on/Roll-off Emission-Free Ships
A5: 900 | B5: 112 | C5: 38.878586 | D5: =$K$3*C5 -> 77.757171 | E5: 3.80473 | F5: =ABS(E5-E4) -> 3.8047001 | G5: =$J$3*E5 -> 34.24257 | H5: 47.693339 | AM5: =$AF$26*E5^2+$AG$26*E5+$AH$26 -> 6.6673703 | AR5: CHECK END OF LIFE INCREASE IN kg | AS5: =AS2+25.29%*AS2 -> 4357.8425
A6: 1200 | B6: 197 | C6: 49.912231 | D6: =$K$3*C6 -> 99.824462 | E6: 10.797176 | F6: =ABS(E6-E5) -> 6.9924463 | G6: =$J$3*E6 -> 97.174587 | H6: 44.148804 | K6: DC BUS VOLTAGE | AM6: =$AF$26*E6^2+$AG$26*E6+$AH$26 -> 17.562042 | AR6: 25.29% increase in kg due to FC degrad
A7: 1500 | B7: 298 | C7: 58.80827 | D7: =$K$3*C7 -> 117.61654 | E7: 20.04236 | F7: =ABS(E7-E6) -> 9.2451837 | G7: =$J$3*E7 -> 180.38124 | H7: 39.815618 | AM7: =$AF$26*E7^2+$AG$26*E7+$AH$26 -> 32.405643
A8: 1800 | B8: 340 | C8: 39.040023 | D8: =$K$3*C8 -> 78.080045 | E8: 29.101907 | F8: =ABS(E8-E7) -> 9.0595467 | G8: =$J$3*E8 -> 261.91716 | H8: 36.028233 | AM8: =$AF$26*E8^2+$AG$26*E8+$AH$26 -> 47.436169
A9: 2100 | B9: 456 | C9: 47.239644 | D9: =$K$3*C9 -> 94.479289 | E9: 39.64277 | F9: =ABS(E9-E8) -> 10.540863 | G9: =$J$3*E9 -> 356.78493 | H9: 32.375565 | AM9: =$AF$26*E9^2+$AG$26*E9+$AH$26 -> 65.528531
A10: 2400 | B10: 289 | C10: -48.697124 | D10: =$K$3*C10 -> -97.394249 | E10: 42.932498 | F10: =ABS(E10-E9) -> 3.2897284 | G10: =$J$3*E10 -> 386.39248 | H10: 32.700149 | AM10: =$AF$26*E10^2+$AG$26*E10+$AH$26 -> 71.30809
A11: 2700 | B11: 189 | C11: -76.440396 | D11: =$K$3*C11 -> -152.88079 | E11: 37.986453 | F11: =ABS(E11-E10) -> 4.9460451 | G11: =$J$3*E11 -> 341.87808 | H11: 37.641983 | AM11: =$AF$26*E11^2+$AG$26*E11+$AH$26 -> 62.64259
A12: 3000 | B12: 141 | C12: -68.00046 | D12: =$K$3*C12 -> -136.00092 | E12: 30.777617 | F12: =ABS(E12-E11) -> 7.2088362 | G12: =$J$3*E12 -> 276.99855 | H12: 43.181674 | AM12: =$AF$26*E12^2+$AG$26*E12+$AH$26 -> 50.268917
A13: 3300 | B13: 134 | C13: -43.627507 | D13: =$K$3*C13 -> -87.255015 | E13: 24.583705 | F13: =ABS(E13-E12) -> 6.193912 | G13: =$J$3*E13 -> 221.25334 | H13: 47.399514 | AM13: =$AF$26*E13^2+$AG$26*E13+$AH$26 -> 39.880097
A14: 3600 | B14: 280 | C14: 29.562073 | D14: =$K$3*C14 -> 59.124147 | E14: 24.541464 | F14: =ABS(E14-E13) -> 0.04224098 | G14: =$J$3*E14 -> 220.87317 | H14: 47.657985 | AM14: =$AF$26*E14^2+$AG$26*E14+$AH$26 -> 39.810018
A15: 3900 | B15: 531 | C15: 69.176027 | D15: =$K$3*C15 -> 138.35205 | E15: 41.285964 | F15: =ABS(E15-E14) -> 16.7445 | G15: =$J$3*E15 -> 371.57368 | H15: 42.717225 | AM15: =$AF$26*E15^2+$AG$26*E15+$AH$26 -> 68.407465
A16: 4200 | B16: 824 | C16: 58.532268 | D16: =$K$3*C16 -> 117.06454 | E16: 73.413278 | F16: =ABS(E16-E15) -> 32.127314 | G16: =$J$3*E16 -> 660.7195 | H16: 37.693597 | AM16: =$AF$26*E16^2+$AG$26*E16+$AH$26 -> 127.86856
A17: 4500 | B17: 835 | C17: 37.299542 | D17: =$K$3*C17 -> 74.599084 | E17: 84.4866 | F17: =ABS(E17-E16) -> 11.073322 | G17: =$J$3*E17 -> 760.3794 | H17: 33.787434 | AM17: =$AF$26*E17^2+$AG$26*E17+$AH$26 -> 149.76201
A18: 4800 | B18: 740 | C18: -24.359877 | D18: =$K$3*C18 -> -48.719753 | E18: 87.6334 | F18: =ABS(E18-E17) -> 3.1467998 | G18: =$J$3*E18 -> 788.7006 | H18: 33.456865 | AM18: =$AF$26*E18^2+$AG$26*E18+$AH$26 -> 156.11452
... A20: 5400 | B20: 877 | C20: 18.076981 | D20: =$K$3*C20 -> 36.153962 | E20: 93.424116 | F20: =ABS(E20-E19) -> 3.8923539 | G20: =$J$3*E20 -> 840.81704 | H20: 32.829302 | AM20: =$AF$26*E20^2+$AG$26*E20+$AH$26 -> 167.95572
A21: 5700 | B21: 874 | C21: 0.95957424 | D21: =$K$3*C21 -> 1.9191485 | E21: 96.894619 | F21: =ABS(E21-E20) -> 3.4705037 | G21: =$J$3*E21 -> 872.05157 | H21: 32.131934 | AF21: Fuel consumption (kW) in y axis | AM21: =$AF$26*E21^2+$AG$26*E21+$AH$26 -> 175.14641
A22: 6000 | B22: 869 | C22: -11.012384 | D22: =$K$3*C22 -> -22.024769 | E22: 98.999326 | F22: =ABS(E22-E21) -> 2.1047063 | G22: =$J$3*E22 -> 890.99393 | H22: 32.556931 | AF22: Power output (kW) in x axis | AM22: =$AF$26*E22^2+$AG$26*E22+$AH$26 -> 179.54156
A23: 6300 | B23: 898 | C23: -4.5424795 | D23: =$K$3*C23 -> -9.0849591 | E23: 100.78346 | F23: =ABS(E23-E22) -> 1.7841314 | G23: =$J$3*E23 -> 907.05111 | H23: 33.148221 | AM23: =$AF$26*E23^2+$AG$26*E23+$AH$26 -> 183.28756
A24: 6600 | B24: 849 | C24: -31.935035 | D24: =$K$3*C24 -> -63.870071 | E24: 101.42657 | F24: =ABS(E24-E23) -> 0.64311382 | G24: =$J$3*E24 -> 912.83914 | H24: 34.638758 | AM24: =$AF$26*E24^2+$AG$26*E24+$AH$26 -> 184.64242
A25: 6900 | B25: 581 | C25: -87.266427 | D25: =$K$3*C25 -> -174.53285 | E25: 87.912996 | F25: =ABS(E25-E24) -> 13.513575 | G25: =$J$3*E25 -> 791.21697 | H25: 40.377071 | AF25: k1 | AG25: k2 | AH25: k3 | AM25: =$AF$26*E25^2+$AG$26*E25+$AH$26 -> 156.68175
A26: 7200 | B26: 528 | C26: -81.107017 | D26: =$K$3*C26 -> -162.21403 | E26: 76.688683 | F26: =ABS(E26-E25) -> 11.224314 | G26: =$J$3*E26 -> 690.19814 | H26: 46.865849 | AF26: 0.00292448 | AG26: 1.51536 | AH26: 0.8595 | AM26: =$AF$26*E26^2+$AG$26*E26+$AH$26 -> 134.26978
A27: 7500 | B27: 656 | C27: 0.036647668 | D27: =$K$3*C27 -> 0.073295335 | E27: 72.878671 | F27: =ABS(E27-E26) -> 3.8100117 | G27: =$J$3*E27 -> 655.90804 | H27: 49.744226 | AM27: =$AF$26*E27^2+$AG$26*E27+$AH$26 -> 126.82972
A28: 7800 | B28: 832 | C28: 69.168901 | D28: =$K$3*C28 -> 138.3378 | E28: 77.071024 | F28: =ABS(E28-E27) -> 4.1923529 | G28: =$J$3*E28 -> 693.63921 | H28: 46.806138 | AM28: =$AF$26*E28^2+$AG$26*E28+$AH$26 -> 135.02109
A29: 8100 | B29: 733 | C29: 0.56675394 | D29: =$K$3*C29 -> 1.1335079 | E29: 81.316771 | F29: =ABS(E29-E28) -> 4.2457471 | G29: =$J$3*E29 -> 731.85094 | H29: 44.279059 | AM29: =$AF$26*E29^2+$AG$26*E29+$AH$26 -> 143.42156
A30: 8400 | B30: 732 | C30: -3.4319386 | D30: =$K$3*C30 -> -6.8638772 | E30: 82.093828 | F30: =ABS(E30-E29) -> 0.77705682 | G30: =$J$3*E30 -> 738.84445 | H30: 44.402888 | AM30: =$AF$26*E30^2+$AG$26*E30+$AH$26 -> 144.97043
A31: 8700 | B31: 734 | C31: -4.5920265 | D31: =$K$3*C31 -> -9.184053 | E31: 82.573804 | F31: =ABS(E31-E30) -> 0.47997666 | G31: =$J$3*E31 -> 743.16424 | H31: 44.718512 | AM31: =$AF$26*E31^2+$AG$26*E31+$AH$26 -> 145.92891
A32: 9000 | B32: 734 | C32: -5.9114019 | D32: =$K$3*C32 -> -11.822804 | E32: 82.866987 | F32: =ABS(E32-E31) -> 0.29318305 | G32: =$J$3*E32 -> 745.80289 | H32: 45.13085 | AM32: =$AF$26*E32^2+$AG$26*E32+$AH$26 -> 146.51504
A33: 9300 | B33: 736 | C33: -5.6792231 | D33: =$K$3*C33 -> -11.358446 | E33: 83.037595 | F33: =ABS(E33-E32) -> 0.17060775 | G33: =$J$3*E33 -> 747.33836 | H33: 45.580784 | AM33: =$AF$26*E33^2+$AG$26*E33+$AH$26 -> 146.85635
A34: 9600 | B34: 741 | C34: -4.074663 | D34: =$K$3*C34 -> -8.1493259 | E34: 83.236557 | F34: =ABS(E34-E33) -> 0.19896199 | G34: =$J$3*E34 -> 749.12901 | H34: 45.955296 | AM34: =$AF$26*E34^2+$AG$26*E34+$AH$26 -> 147.2546
A35: 9900 | B35: 749 | C35: -1.6705552 | D35: =$K$3*C35 -> -3.3411104 | E35: 83.591165 | F35: =ABS(E35-E34) -> 0.35460787 | G35: =$J$3*E35 -> 752.32049 | H35: 46.171688 | AF35: BATTERY DEGRADATION | AM35: =$AF$26*E35^2+$AG$26*E35+$AH$26 -> 147.96496
A36: 10200 | B36: 744 | C36: -5.2588815 | D36: =$K$3*C36 -> -10.517763 | E36: 83.833051 | F36: =ABS(E36-E35) -> 0.24188569 | G36: =$J$3*E36 -> 754.49746 | H36: 46.45158 | AM36: =$AF$26*E36^2+$AG$26*E36+$AH$26 -> 148.44994
A37: 10500 | B37: 746 | C37: -4.5046318 | D37: =$K$3*C37 -> -9.0092637 | E37: 83.88763 | F37: =ABS(E37-E36) -> 0.054579436 | G37: =$J$3*E37 -> 754.98867 | H37: 46.828873 | AM37: =$AF$26*E37^2+$AG$26*E37+$AH$26 -> 148.55942
A38: 10800 | B38: 736 | C38: -8.6175559 | D38: =$K$3*C38 -> -17.235112 | E38: 83.690562 | F38: =ABS(E38-E37) -> 0.19706844 | G38: =$J$3*E38 -> 753.21506 | H38: 47.35061 | AM38: =$AF$26*E38^2+$AG$26*E38+$AH$26 -> 148.16421
A39: 11100 | B39: 733 | C39: -8.0424634 | D39: =$K$3*C39 -> -16.084927 | E39: 83.229432 | F39: =ABS(E39-E38) -> 0.46112998 | G39: =$J$3*E39 -> 749.06489 | H39: 47.995886 | AM39: =$AF$26*E39^2+$AG$26*E39+$AH$26 -> 147.24033
A40: 11400 | B40: 766 | C40: 7.0689045 | D40: =$K$3*C40 -> 14.137809 | E40: 83.537855 | F40: =ABS(E40-E39) -> 0.30842375 | G40: =$J$3*E40 -> 751.8407 | H40: 47.989111 | AM40: =$AF$26*E40^2+$AG$26*E40+$AH$26 -> 147.85812
A41: 11700 | B41: 716 | C41: -16.810255 | D41: =$K$3*C41 -> -33.62051 | E41: 83.28912 | F41: =ABS(E41-E40) -> 0.24873502 | G41: =$J$3*E41 -> 749.60208 | H41: 48.436448 | AM41: =$AF$26*E41^2+$AG$26*E41+$AH$26 -> 147.35985
...

Sheet Maneuv_Amsterdam_600LPF_125AH
A1: Time (sec) | B1: Load Profile (kW) | C1: Battery power (kW) | D1: Total Batt Power (kW) | E1: FC power (kW) | F1: Abs(Pfc(t)-Pfc(t-1) | G1: TotalFC power(kw) | H1: Battery SoC (%) | AK1: Sampling_dt(sec) | AL1: Sampling_dt(hrs) | AM1: Fuel consumption (f(pfc)) for 1 FC (kW) | AN1: Addit_Ploss(kW) | AO1: Fctotal(kw) | AQ1: FC_total*hrs(kwh) | AR1: Ke-m ( kg/kwh) | AS1: Fuel consumption (kg) | AU1: H2 in $/kg | AV1: Fuel cost | AW1: H2 price in $/kwh | AY1: Fuel cost ($)
A2: 0 | B2: 0 | C2: 12.350136 | D2: =$K$3*C2 -> 24.700273 | E2: 0 | F2: 0 | G2: =$J$3*E2 -> 0 | H2: 50 | J2: Nfc | K2: Nbat | AK2: 300 | AL2: =AK2/3600 -> 0.083333333 | AM2: =$AF$26*E2^2+$AG$26*E2+$AH$26 -> 0.8595 | AO2: =J3*AM70+AN2 -> 27481.733 | AQ2: =AO2*AL2 -> 2290.1444 | AR2: 0.03 | AS2: =AQ2*AR2 -> 68.704333 | AU2: 4 | AV2: =AU2*AS2 -> 274.81733 | AW2: =AU2/33.35 -> 0.11994003 | AY2: =AQ2*AW2 -> 274.67999
A3: 300 | B3: 0 | C3: -0.075000176 | D3: =$K$3*C3 -> -0.15000035 | E3: 0.016667063 | F3: =ABS(E3-E2) -> 0.016667063 | G3: =$J$3*E3 -> 0.15000356 | H3: 50.542869 | J3: 9 | K3: 2 | AM3: =$AF$26*E3^2+$AG$26*E3+$AH$26 -> 0.88475741
A4: 600 | B4: 28 | C4: 13.999915 | D4: =$K$3*C4 -> 27.99983 | E4: 2.9905002e-05 | F4: =ABS(E4-E3) -> 0.016637158 | G4: =$J$3*E4 -> 0.00026914502 | H4: 50.001184 | AG4: Fuel consumption | AM4: =$AF$26*E4^2+$AG$26*E4+$AH$26 -> 0.85954532 | AR4: *Source: Cost-effective control of Roll-on/Roll-off Emission-Free Ships
A5: 900 | B5: 86 | C5: 28.717026 | D5: =$K$3*C5 -> 57.434051 | E5: 3.1739923 | F5: =ABS(E5-E4) -> 3.1739624 | G5: =$J$3*E5 -> 28.565931 | H5: 48.10525 | AM5: =$AF$26*E5^2+$AG$26*E5+$AH$26 -> 5.6987029 | AR5: CHECK END OF LIFE INCREASE IN kg | AS5: =AS2+25.29%*AS2 -> 86.079659
A6: 1200 | B6: 110 | C6: 22.883581 | D6: =$K$3*C6 -> 45.767162 | E6: 7.1369479 | F6: =ABS(E6-E5) -> 3.9629556 | G6: =$J$3*E6 -> 64.232531 | H6: 46.08244 | K6: DC BUS VOLTAGE | AM6: =$AF$26*E6^2+$AG$26*E6+$AH$26 -> 11.823507 | AR6: 25.29% increase in kg due to FC degrad
A7: 1500 | B7: 139 | C7: 19.693398 | D7: =$K$3*C7 -> 39.386797 | E7: 11.068079 | F7: =ABS(E7-E6) -> 3.9311315 | G7: =$J$3*E7 -> 99.612715 | H7: 44.426659 | AM7: =$AF$26*E7^2+$AG$26*E7+$AH$26 -> 17.989881
A8: 1800 | B8: 146 | C8: 8.7260592 | D8: =$K$3*C8 -> 17.452118 | E8: 14.283035 | F8: =ABS(E8-E7) -> 3.2149557 | G8: =$J$3*E8 -> 128.54732 | H8: 43.358343 | AM8: =$AF$26*E8^2+$AG$26*E8+$AH$26 -> 23.100049
A9: 2100 | B9: 162 | C9: 5.6236506 | D9: =$K$3*C9 -> 11.247301 | E9: 16.750214 | F9: =ABS(E9-E8) -> 2.467179 | G9: =$J$3*E9 -> 150.75193 | H9: 42.810147 | AM9: =$AF$26*E9^2+$AG$26*E9+$AH$26 -> 27.062625
A10: 2400 | B10: 121 | C10: -17.474019 | D10: =$K$3*C10 -> -34.948037 | E10: 17.327503 | F10: =ABS(E10-E9) -> 0.57728893 | G10: =$J$3*E10 -> 155.94753 | H10: 43.361657 | AM10: =$AF$26*E10^2+$AG$26*E10+$AH$26 -> 27.994958
A11: 2700 | B11: 142 | C11: -6.1262091 | D11: =$K$3*C11 -> -12.252418 | E11: 17.139069 | F11: =ABS(E11-E10) -> 0.18843435 | G11: =$J$3*E11 -> 154.25162 | H11: 44.235544 | AM11: =$AF$26*E11^2+$AG$26*E11+$AH$26 -> 27.690418
A12: 3000 | B12: 156 | C12: -2.1780522 | D12: =$K$3*C12 -> -4.3561044 | E12: 17.817253 | F12: =ABS(E12-E11) -> 0.67818416 | G12: =$J$3*E12 -> 160.35528 | H12: 44.543655 | AM12: =$AF$26*E12^2+$AG$26*E12+$AH$26 -> 28.787442
A13: 3300 | B13: 135 | C13: -12.870187 | D13: =$K$3*C13 -> -25.740373 | E13: 17.859969 | F13: =ABS(E13-E12) -> 0.042716315 | G13: =$J$3*E13 -> 160.73972 | H13: 45.171078 | AM13: =$AF$26*E13^2+$AG$26*E13+$AH$26 -> 28.856629
A14: 3600 | B14: 164 | C14: 0.54815016 | D14: =$K$3*C14 -> 1.0963003 | E14: 18.100307 | F14: =ABS(E14-E13) -> 0.24033806 | G14: =$J$3*E14 -> 162.90277 | H14: 45.598165 | AM14: =$AF$26*E14^2+$AG$26*E14+$AH$26 -> 29.246103
A15: 3900 | B15: 281 | C15: 40.476391 | D15: =$K$3*C15 -> 80.952783 | E15: 22.22722 | F15: =ABS(E15-E14) -> 4.1269124 | G15: =$J$3*E15 -> 200.04498 | H15: 43.831393 | AM15: =$AF$26*E15^2+$AG$26*E15+$AH$26 -> 35.986577
A16: 4200 | B16: 332 | C16: 35.799983 | D16: =$K$3*C16 -> 71.599966 | E16: 28.93303 | F16: =ABS(E16-E15) -> 6.7058106 | G16: =$J$3*E16 -> 260.39727 | H16: 40.85029 | AM16: =$AF$26*E16^2+$AG$26*E16+$AH$26 -> 47.151598
A17: 4500 | B17: 466 | C17: 56.873216 | D17: =$K$3*C17 -> 113.74643 | E17: 38.498336 | F17: =ABS(E17-E16) -> 9.5653059 | G17: =$J$3*E17 -> 346.48503 | H17: 36.898841 | AM17: =$AF$26*E17^2+$AG$26*E17+$AH$26 -> 63.532775
A18: 4800 | B18: 473 | C18: 25.543141 | D18: =$K$3*C18 -> 51.086283 | E18: 46.878665 | F18: =ABS(E18-E17) -> 8.3803289 | G18: =$J$3*E18 -> 421.90799 | H18: 33.69626 | AM18: =$AF$26*E18^2+$AG$26*E18+$AH$26 -> 78.324418
... A20: 5400 | B20: 471 | C20: -10.654814 | D20: =$K$3*C20 -> -21.309628 | E20: 54.700229 | F20: =ABS(E20-E19) -> 2.8291774 | G20: =$J$3*E20 -> 492.30207 | H20: 32.960865 | AM20: =$AF$26*E20^2+$AG$26*E20+$AH$26 -> 92.500421
A21: 5700 | B21: 461 | C21: -21.071925 | D21: =$K$3*C21 -> -42.14385 | E21: 55.904003 | F21: =ABS(E21-E20) -> 1.2037733 | G21: =$J$3*E21 -> 503.13603 | H21: 34.235064 | AF21: Fuel consumption (kW) in y axis | AM21: =$AF$26*E21^2+$AG$26*E21+$AH$26 -> 94.713943
A22: 6000 | B22: 433 | C22: -33.063363 | D22: =$K$3*C22 -> -66.126725 | E22: 55.457705 | F22: =ABS(E22-E21) -> 0.44629786 | G22: =$J$3*E22 -> 499.11934 | H22: 36.382416 | AF22: Power output (kW) in x axis | AM22: =$AF$26*E22^2+$AG$26*E22+$AH$26 -> 93.892293
A23: 6300 | B23: 371 | C23: -51.512096 | D23: =$K$3*C23 -> -103.02419 | E23: 52.668678 | F23: =ABS(E23-E22) -> 2.7890268 | G23: =$J$3*E23 -> 474.0181 | H23: 39.723377 | AM23: =$AF$26*E23^2+$AG$26*E23+$AH$26 -> 88.783985
A24: 6600 | B24: 467 | C24: 1.1074656 | D24: =$K$3*C24 -> 2.2149313 | E24: 51.64181 | F24: =ABS(E24-E23) -> 1.0268684 | G24: =$J$3*E24 -> 464.77629 | H24: 41.496658 | AM24: =$AF$26*E24^2+$AG$26*E24+$AH$26 -> 86.91466
A25: 6900 | B25: 467 | C25: -5.0348359 | D25: =$K$3*C25 -> -10.069672 | E25: 53.006945 | F25: =ABS(E25-E24) -> 1.3651351 | G25: =$J$3*E25 -> 477.0625 | H25: 41.671192 | AF25: k1 | AG25: k2 | AH25: k3 | AM25: =$AF$26*E25^2+$AG$26*E25+$AH$26 -> 89.401121
A26: 7200 | B26: 468 | C26: -7.965986 | D26: =$K$3*C26 -> -15.931972 | E26: 53.769394 | F26: =ABS(E26-E25) -> 0.76244875 | G26: =$J$3*E26 -> 483.92454 | H26: 42.187806 | AF26: 0.00292448 | AG26: 1.51536 | AH26: 0.8595 | AM26: =$AF$26*E26^2+$AG$26*E26+$AH$26 -> 90.794592
A27: 7500 | B27: 467 | C27: -10.035892 | D27: =$K$3*C27 -> -20.071785 | E27: 54.118253 | F27: =ABS(E27-E26) -> 0.3488598 | G27: =$J$3*E27 -> 487.06428 | H27: 42.895633 | AM27: =$AF$26*E27^2+$AG$26*E27+$AH$26 -> 91.433311
A28: 7800 | B28: 558 | C28: 24.652654 | D28: =$K$3*C28 -> 49.305308 | E28: 56.520477 | F28: =ABS(E28-E27) -> 2.4022235 | G28: =$J$3*E28 -> 508.68429 | H28: 42.203267 | AM28: =$AF$26*E28^2+$AG$26*E28+$AH$26 -> 95.850809
A29: 8100 | B29: 451 | C29: -32.417002 | D29: =$K$3*C29 -> -64.834003 | E29: 57.314211 | F29: =ABS(E29-E28) -> 0.79373373 | G29: =$J$3*E29 -> 515.8279 | H29: 42.695644 | AM29: =$AF$26*E29^2+$AG$26*E29+$AH$26 -> 97.317841
A30: 8400 | B30: 141 | C30: -87.547079 | D30: =$K$3*C30 -> -175.09416 | E30: 35.921266 | F30: =ABS(E30-E29) -> 21.392944 | G30: =$J$3*E30 -> 323.2914 | H30: 48.515095 | AM30: =$AF$26*E30^2+$AG$26*E30+$AH$26 -> 59.066716
A31: 8700 | B31: 204 | C31: -23.541206 | D31: =$K$3*C31 -> -47.082413 | E31: 27.897752 | F31: =ABS(E31-E30) -> 8.0235141 | G31: =$J$3*E31 -> 251.07977 | H31: 52.54939 | AM31: =$AF$26*E31^2+$AG$26*E31+$AH$26 -> 45.410715
A32: 9000 | B32: 236 | C32: 1.3258596 | D32: =$K$3*C32 -> 2.6517191 | E32: 25.927377 | F32: =ABS(E32-E31) -> 1.9703752 | G32: =$J$3*E32 -> 233.34639 | H32: 53.316583 | AF32: BATTERY DEGRADATION | AM32: =$AF$26*E32^2+$AG$26*E32+$AH$26 -> 42.11473
A33: 9300 | B33: 138 | C33: -33.483933 | D33: =$K$3*C33 -> -66.967865 | E33: 22.774134 | F33: =ABS(E33-E32) -> 3.1532428 | G33: =$J$3*E33 -> 204.96721 | H33: 54.694405 | AM33: =$AF$26*E33^2+$AG$26*E33+$AH$26 -> 36.887326
A34: 9600 | B34: 120 | C34: -20.834298 | D34: =$K$3*C34 -> -41.668595 | E34: 17.963094 | F34: =ABS(E34-E33) -> 4.81104 | G34: =$J$3*E34 -> 161.66785 | H34: 56.74734 | AM34: =$AF$26*E34^2+$AG$26*E34+$AH$26 -> 29.023704
A35: 9900 | B35: 119 | C35: -6.2977762 | D35: =$K$3*C35 -> -12.595552 | E35: 14.621673 | F35: =ABS(E35-E34) -> 3.3414211 | G35: =$J$3*E35 -> 131.59506 | H35: 57.74262 | AM35: =$AF$26*E35^2+$AG$26*E35+$AH$26 -> 23.641833
A36: 10200 | B36: 120 | C36: 2.7496072 | D36: =$K$3*C36 -> 5.4992143 | E36: 12.722269 | F36: =ABS(E36-E35) -> 1.899404 | G36: =$J$3*E36 -> 114.50042 | H36: 57.844883 | AM36: =$AF$26*E36^2+$AG$26*E36+$AH$26 -> 20.611663
A37: 10500 | B37: 120 | C37: 7.1427621 | D37: =$K$3*C37 -> 14.285524 | E37: 11.746018 | F37: =ABS(E37-E36) -> 0.97625086 | G37: =$J$3*E37 -> 105.71416 | H37: 57.442685 | AM37: =$AF$26*E37^2+$AG$26*E37+$AH$26 -> 19.062434
A38: 10800 | B38: 101 | C38: 2.1231858 | D38: =$K$3*C38 -> 4.2463716 | E38: 10.750379 | F38: =ABS(E38-E37) -> 0.99563957 | G38: =$J$3*E38 -> 96.753408 | H38: 57.102168 | AM38: =$AF$26*E38^2+$AG$26*E38+$AH$26 -> 17.488178
A39: 11100 | B39: 113 | C39: 10.695265 | D39: =$K$3*C39 -> 21.390529 | E39: 10.178801 | F39: =ABS(E39-E38) -> 0.57157744 | G39: =$J$3*E39 -> 91.609211 | H39: 56.569094 | AM39: =$AF$26*E39^2+$AG$26*E39+$AH$26 -> 16.587048
A40: 11400 | B40: 131 | C40: 16.940244 | D40: =$K$3*C40 -> 33.880488 | E40: 10.791019 | F40: =ABS(E40-E39) -> 0.61221786 | G40: =$J$3*E40 -> 97.119172 | H40: 55.466901 | AM40: =$AF$26*E40^2+$AG$26*E40+$AH$26 -> 17.552323
A41: 11700 | B41: 149 | C41: 19.369979 | D41: =$K$3*C41 -> 38.739959 | E41: 12.251065 | F41: =ABS(E41-E40) -> 1.4600459 | G41: =$J$3*E41 -> 110.25958 | H41: 54.040111 | AM41: =$AF$26*E41^2+$AG$26*E41+$AH$26 -> 19.863205
...

Sheet Amsterd_Lithuania_600LPF_125Ah
A1: Time (sec) | B1: Load Profile (kW) | C1: Battery power (kW) | D1: Total Batt Power (kW) | E1: FC power (kW) | F1: Abs(Pfc(t)-Pfc(t-1) | G1: TotalFC power(kw) | H1: Battery SoC (%) | AK1: Sampling_dt(sec) | AL1: Sampling_dt(hrs) | AM1: Fuel consumption (f(pfc)) for 1 FC (kW) | AN1: Addit_Ploss(kW) | AO1: Fctotal(kw) | AQ1: FC_total*hrs(kwh) | AR1: Ke-m ( kg/kwh) | AS1: Fuel consumption (kg) | AU1: H2 in $/kg | AV1: Fuel cost | AW1: H2 price in $/kwh | AY1: Fuel cost ($) | BB1: FUEL CONSUMPTION CALCULATION ALTERNATIVE | BG1: Fuel consumption (f(pfc)) for 1 FC (kW) | BI1: Total FC (kg)
A2: 0 | B2: 0 | C2: 12.350136 | D2: =$K$3*C2 -> 24.700273 | E2: 0 | F2: 0 | G2: =$J$3*E2 -> 0 | H2: 50 | J2: Nfc | K2: Nbat | AK2: 300 | AL2: =AK2/3600 -> 0.083333333 | AM2: =$AF$26*E2^2+$AG$26*E2+$AH$26 -> 0.8595 | AO2: =J3*AM1586+AN2 -> 1938568.7 | AQ2: =AO2*AL2 -> 161547.39 | AR2: 0.03 | AS2: =AQ2*AR2 -> 4846.4218 | AU2: 4 | AV2: =AU2*AS2 -> 19385.687 | AW2: =AU2/33.35 -> 0.11994003 | AY2: =AQ2*AW2 -> 19375.999 | BG2: =$BC$5*E2^2+$BD$5*E2+$BE$5 -> 0.08 | BI2: =J3*BG1586*AL2 -> 4881.5789
A3: 300 | B3: 0 | C3: -0.075000176 | D3: =$K$3*C3 -> -0.15000035 | E3: 0.016667063 | F3: =ABS(E3-E2) -> 0.016667063 | G3: =$J$3*E3 -> 0.15000356 | H3: 50.542869 | J3: 9 | K3: 2 | AM3: =$AF$26*E3^2+$AG$26*E3+$AH$26 -> 0.88475741 | BC3: FUNCTION OF Kg now the FC | BG3: =$BC$5*E3^2+$BD$5*E3+$BE$5 -> 0.080739545
A4: 600 | B4: 18 | C4: 8.9998975 | D4: =$K$3*C4 -> 17.999795 | E4: 2.968684e-05 | F4: =ABS(E4-E3) -> 0.016637376 | G4: =$J$3*E4 -> 0.00026718156 | H4: 50.195227 | AG4: Fuel consumption | AM4: =$AF$26*E4^2+$AG$26*E4+$AH$26 -> 0.85954499 | AR4: *Source: Cost-effective control of Roll-on/Roll-off Emission-Free Ships | BC4: k1 | BD4: k2 | BE4: k3 | BG4: =$BC$5*E4^2+$BD$5*E4+$BE$5 -> 0.080001317
A5: 900 | B5: 64 | C5: 24.092738 | D5: =$K$3*C5 -> 48.185476 | E5: 1.7571587 | F5: =ABS(E5-E4) -> 1.757129 | G5: =$J$3*E5 -> 15.814428 | H5: 48.711771 | AM5: =$AF$26*E5^2+$AG$26*E5+$AH$26 -> 3.5312576 | AR5: CHECK END OF LIFE INCREASE IN kg | AS5: =AS2+25.29%*AS2 -> 6072.0819 | BC5: 9.712e-05 | BD5: 0.04437 | BE5: 0.08 | BG5: =$BC$5*E5^2+$BD$5*E5+$BE$5 -> 0.158265
A6: 1200 | B6: 112 | C6: 28.969368 | D6: =$K$3*C6 -> 57.938737 | E6: 6.0067738 | F6: =ABS(E6-E5) -> 4.2496151 | G6: =$J$3*E6 -> 54.060964 | H6: 46.651405 | K6: DC BUS VOLTAGE | AM6: =$AF$26*E6^2+$AG$26*E6+$AH$26 -> 10.067444 | AR6: 25.29% increase in kg due to FC degrad | BG6: =$BC$5*E6^2+$BD$5*E6+$BE$5 -> 0.35002477
A7: 1500 | B7: 139 | C7: 22.556263 | D7: =$K$3*C7 -> 45.112525 | E7: 10.431889 | F7: =ABS(E7-E6) -> 4.4251149 | G7: =$J$3*E7 -> 93.886998 | H7: 44.655189 | AM7: =$AF$26*E7^2+$AG$26*E7+$AH$26 -> 16.985821 | BG7: =$BC$5*E7^2+$BD$5*E7+$BE$5 -> 0.55343191
A8: 1800 | B8: 138 | C8: 7.4215484 | D8: =$K$3*C8 -> 14.843097 | E8: 13.684045 | F8: =ABS(E8-E7) -> 3.2521568 | G8: =$J$3*E8 -> 123.15641 | H8: 43.5421 | AM8: =$AF$26*E8^2+$AG$26*E8+$AH$26 -> 22.143373 | BG8: =$BC$5*E8^2+$BD$5*E8+$BE$5 -> 0.70534712
A9: 2100 | B9: 170 | C9: 10.986146 | D9: =$K$3*C9 -> 21.972292 | E9: 16.44743 | F9: =ABS(E9-E8) -> 2.7633842 | G9: =$J$3*E9 -> 148.02687 | H9: 42.808636 | AM9: =$AF$26*E9^2+$AG$26*E9+$AH$26 -> 26.574401 | BG9: =$BC$5*E9^2+$BD$5*E9+$BE$5 -> 0.83604516
A10: 2400 | B10: 183 | C10: 5.3228848 | D10: =$K$3*C10 -> 10.64577 | E10: 19.150362 | F10: =ABS(E10-E9) -> 2.7029324 | G10: =$J$3*E10 -> 172.35326 | H10: 42.193823 | AM10: =$AF$26*E10^2+$AG$26*E10+$AH$26 -> 30.951706 | BG10: =$BC$5*E10^2+$BD$5*E10+$BE$5 -> 0.965319
A11: 2700 | B11: 222 | C11: 11.62693 | D11: =$K$3*C11 -> 23.253859 | E11: 22.08274 | F11: =ABS(E11-E10) -> 2.932378 | G11: =$J$3*E11 -> 198.74466 | H11: 41.506774 | AM11: =$AF$26*E11^2+$AG$26*E11+$AH$26 -> 35.748916 | BG11: =$BC$5*E11^2+$BD$5*E11+$BE$5 -> 1.1071715
A12: 3000 | B12: 144 | C12: -29.043456 | D12: =$K$3*C12 -> -58.086913 | E12: 22.454028 | F12: =ABS(E12-E11) -> 0.37128833 | G12: =$J$3*E12 -> 202.08626 | H12: 42.340327 | AM12: =$AF$26*E12^2+$AG$26*E12+$AH$26 -> 36.359911 | BG12: =$BC$5*E12^2+$BD$5*E12+$BE$5 -> 1.1252515
A13: 3300 | B13: 145 | C13: -20.369948 | D13: =$K$3*C13 -> -40.739896 | E13: 20.637649 | F13: =ABS(E13-E12) -> 1.8163791 | G13: =$J$3*E13 -> 185.73884 | H13: 44.225671 | AM13: =$AF$26*E13^2+$AG$26*E13+$AH$26 -> 33.378541 | BG13: =$BC$5*E13^2+$BD$5*E13+$BE$5 -> 1.0370571
A14: 3600 | B14: 154 | C14: -11.474392 | D14: =$K$3*C14 -> -22.948784 | E14: 19.660867 | F14: =ABS(E14-E13) -> 0.9767821 | G14: =$J$3*E14 -> 176.94781 | H14: 45.428963 | AM14: =$AF$26*E14^2+$AG$26*E14+$AH$26 -> 31.783249 | BG14: =$BC$5*E14^2+$BD$5*E14+$BE$5 -> 0.98989439
A15: 3900 | B15: 314 | C15: 50.086181 | D15: =$K$3*C15 -> 100.17236 | E15: 23.758305 | F15: =ABS(E15-E14) -> 4.0974373 | G15: =$J$3*E15 -> 213.82474 | H15: 43.668668 | AM15: =$AF$26*E15^2+$AG$26*E15+$AH$26 -> 38.512628 | BG15: =$BC$5*E15^2+$BD$5*E15+$BE$5 -> 1.188976
A16: 4200 | B16: 397 | C16: 52.770246 | D16: =$K$3*C16 -> 105.54049 | E16: 32.38395 | F16: =ABS(E16-E15) -> 8.6256453 | G16: =$J$3*E16 -> 291.45555 | H16: 39.599721 | AM16: =$AF$26*E16^2+$AG$26*E16+$AH$26 -> 52.999804 | BG16: =$BC$5*E16^2+$BD$5*E16+$BE$5 -> 1.6187276
A17: 4500 | B17: 591 | C17: 53.033766 | D17: =$K$3*C17 -> 106.06753 | E17: 51.989841 | F17: =ABS(E17-E16) -> 19.605891 | G17: =$J$3*E17 -> 467.90857 | H17: 35.105498 | AM17: =$AF$26*E17^2+$AG$26*E17+$AH$26 -> 87.547529 | BG17: =$BC$5*E17^2+$BD$5*E17+$BE$5 -> 2.6492991
A18: 4800 | B18: 595 | C18: 23.678819 | D18: =$K$3*C18 -> 47.357637 | E18: 60.848053 | F18: =ABS(E18-E17) -> 8.8582121 | G18: =$J$3*E18 -> 547.63247 | H18: 32.060334 | AM18: =$AF$26*E18^2+$AG$26*E18+$AH$26 -> 103.89405 | BG18: =$BC$5*E18^2+$BD$5*E18+$BE$5 -> 3.1394135
... A20: 5400 | B20: 600 | C20: -9.0330137 | D20: =$K$3*C20 -> -18.066027 | E20: 68.672579 | F20: =ABS(E20-E19) -> 2.9883277 | G20: =$J$3*E20 -> 618.05321 | H20: 31.367721 | AM20: =$AF$26*E20^2+$AG$26*E20+$AH$26 -> 118.7148 | BG20: =$BC$5*E20^2+$BD$5*E20+$BE$5 -> 3.5850128
A21: 5700 | B21: 606 | C21: -14.558809 | D21: =$K$3*C21 -> -29.117618 | E21: 70.567096 | F21: =ABS(E21-E20) -> 1.8945166 | G21: =$J$3*E21 -> 635.10386 | H21: 32.308115 | S21: This profile determines the battery size | AF21: Fuel consumption (kW) in y axis | AM21: =$AF$26*E21^2+$AG$26*E21+$AH$26 -> 122.35713 | BG21: =$BC$5*E21^2+$BD$5*E21+$BE$5 -> 3.694692
A22: 6000 | B22: 540 | C22: -45.467281 | D22: =$K$3*C22 -> -90.934563 | E22: 70.102548 | F22: =ABS(E22-E21) -> 0.46454776 | G22: =$J$3*E22 -> 630.92293 | H22: 34.740482 | S22: largest SoC range…from about 25-79% | AF22: Power output (kW) in x axis | AM22: =$AF$26*E22^2+$AG$26*E22+$AH$26 -> 121.46207 | BG22: =$BC$5*E22^2+$BD$5*E22+$BE$5 -> 3.6677334
A23: 6300 | B23: 495 | C23: -53.897336 | D23: =$K$3*C23 -> -107.79467 | E23: 66.975941 | F23: =ABS(E23-E22) -> 3.1266071 | G23: =$J$3*E23 -> 602.78347 | H23: 38.61583 | S23: so we can say 20-80% we size the battery | AM23: =$AF$26*E23^2+$AG$26*E23+$AH$26 -> 115.47073 | BG23: =$BC$5*E23^2+$BD$5*E23+$BE$5 -> 3.4873811
A24: 6600 | B24: 504 | C24: -35.090623 | D24: =$K$3*C24 -> -70.181246 | E24: 63.796662 | F24: =ABS(E24-E23) -> 3.179279 | G24: =$J$3*E24 -> 574.16996 | H24: 42.000269 | AM24: =$AF$26*E24^2+$AG$26*E24+$AH$26 -> 109.43708 | BG24: =$BC$5*E24^2+$BD$5*E24+$BE$5 -> 3.3059377
A25: 6900 | B25: 503 | C25: -25.775313 | D25: =$K$3*C25 -> -51.550625 | E25: 61.615611 | F25: =ABS(E25-E24) -> 2.1810512 | G25: =$J$3*E25 -> 554.5405 | H25: 44.328994 | S25: from matlab code Pbatmax= 96.5 KW | AF25: k1 | AG25: k2 | AH25: k3 | AM25: =$AF$26*E25^2+$AG$26*E25+$AH$26 -> 105.33207 | BG25: =$BC$5*E25^2+$BD$5*E25+$BE$5 -> 3.1825991
A26: 7200 | B26: 415 | C26: -52.561791 | D26: =$K$3*C26 -> -105.12358 | E26: 57.790725 | F26: =ABS(E26-E25) -> 3.8248862 | G26: =$J$3*E26 -> 520.11652 | H26: 47.445292 | S26: Ebatmax =96.5kwh | AF26: 0.00292448 | AG26: 1.51536 | AH26: 0.8595 | AM26: =$AF$26*E26^2+$AG$26*E26+$AH$26 -> 98.200337 | BG26: =$BC$5*E26^2+$BD$5*E26+$BE$5 -> 2.9685327
A27: 7500 | B27: 415 | C27: -31.480737 | D27: =$K$3*C27 -> -62.961473 | E27: 53.105999 | F27: =ABS(E27-E26) -> 4.6847259 | G27: =$J$3*E27 -> 477.95399 | H27: 50.620863 | S27: so we say Ebatmax = 100 kwh | AM27: =$AF$26*E27^2+$AG$26*E27+$AH$26 -> 89.581962 | BG27: =$BC$5*E27^2+$BD$5*E27+$BE$5 -> 2.7102156
A28: 7800 | B28: 419 | C28: -15.68602 | D28: =$K$3*C28 -> -31.37204 | E28: 50.040611 | F28: =ABS(E28-E27) -> 3.0653875 | G28: =$J$3*E28 -> 450.3655 | H28: 52.393061 | AM28: =$AF$26*E28^2+$AG$26*E28+$AH$26 -> 84.012122 | BG28: =$BC$5*E28^2+$BD$5*E28+$BE$5 -> 2.5434965
A29: 8100 | B29: 421 | C29: -6.3458551 | D29: =$K$3*C29 -> -12.69171 | E29: 48.187308 | F29: =ABS(E29-E28) -> 1.8533033 | G29: =$J$3*E29 -> 433.68577 | H29: 53.215303 | AM29: =$AF$26*E29^2+$AG$26*E29+$AH$26 -> 80.67131 | BG29: =$BC$5*E29^2+$BD$5*E29+$BE$5 -> 2.4435851
A30: 8400 | B30: 413 | C30: -4.3899172 | D30: =$K$3*C30 -> -8.7798344 | E30: 46.863826 | F30: =ABS(E30-E29) -> 1.323482 | G30: =$J$3*E30 -> 421.77443 | H30: 53.625445 | AM30: =$AF$26*E30^2+$AG$26*E30+$AH$26 -> 78.297864 | BG30: =$BC$5*E30^2+$BD$5*E30+$BE$5 -> 2.3726447
A31: 8700 | B31: 413 | C31: 0.038690689 | D31: =$K$3*C31 -> 0.077381377 | E31: 45.879703 | F31: =ABS(E31-E30) -> 0.98412255 | G31: =$J$3*E31 -> 412.91733 | H31: 53.778844 | AM31: =$AF$26*E31^2+$AG$26*E31+$AH$26 -> 76.539643 | BG31: =$BC$5*E31^2+$BD$5*E31+$BE$5 -> 2.3201149
A32: 9000 | B32: 412 | C32: 2.2117548 | D32: =$K$3*C32 -> 4.4235095 | E32: 45.285708 | F32: =ABS(E32-E31) -> 0.59399534 | G32: =$J$3*E32 -> 407.57137 | H32: 53.683591 | AM32: =$AF$26*E32^2+$AG$26*E32+$AH$26 -> 75.481161 | BG32: =$BC$5*E32^2+$BD$5*E32+$BE$5 -> 2.2885001
A33: 9300 | B33: 411 | C33: 3.3451239 | D33: =$K$3*C33 -> 6.6902479 | E33: 44.922747 | F33: =ABS(E33-E32) -> 0.36296093 | G33: =$J$3*E33 -> 404.30472 | H33: 53.463389 | AF33: BATTERY DEGRADATION | AM33: =$AF$26*E33^2+$AG$26*E33+$AH$26 -> 74.83539 | BG33: =$BC$5*E33^2+$BD$5*E33+$BE$5 -> 2.2692156
A34: 9600 | B34: 417 | C34: 6.4801827 | D34: =$K$3*C34 -> 12.960365 | E34: 44.892722 | F34: =ABS(E34-E33) -> 0.030025294 | G34: =$J$3*E34 -> 404.0345 | H34: 53.069725 | AM34: =$AF$26*E34^2+$AG$26*E34+$AH$26 -> 74.782005 | BG34: =$BC$5*E34^2+$BD$5*E34+$BE$5 -> 2.2676215
A35: 9900 | B35: 410 | C35: 2.9902022 | D35: =$K$3*C35 -> 5.9804043 | E35: 44.89052 | F35: =ABS(E35-E34) -> 0.0022014966 | G35: =$J$3*E35 -> 404.01468 | H35: 52.713676 | AM35: =$AF$26*E35^2+$AG$26*E35+$AH$26 -> 74.778091 | BG35: =$BC$5*E35^2+$BD$5*E35+$BE$5 -> 2.2675046
A36: 10200 | B36: 410 | C36: 3.4924576 | D36: =$K$3*C36 -> 6.9849153 | E36: 44.778897 | F36: =ABS(E36-E35) -> 0.11162294 | G36: =$J$3*E36 -> 403.01008 | H36: 52.459647 | AM36: =$AF$26*E36^2+$AG$26*E36+$AH$26 -> 74.57967 | BG36: =$BC$5*E36^2+$BD$5*E36+$BE$5 -> 2.2615798
A37: 10500 | B37: 416 | C37: 5.876584 | D37: =$K$3*C37 -> 11.753168 | E37: 44.915743 | F37: =ABS(E37-E36) -> 0.13684591 | G37: =$J$3*E37 -> 404.24169 | H37: 52.086374 | AM37: =$AF$26*E37^2+$AG$26*E37+$AH$26 -> 74.822937 | BG37: =$BC$5*E37^2+$BD$5*E37+$BE$5 -> 2.2688438
A38: 10800 | B38: 427 | C38: 8.8341852 | D38: =$K$3*C38 -> 17.66837 | E38: 45.480696 | F38: =ABS(E38-E37) -> 0.56495261 | G38: =$J$3*E38 -> 409.32626 | H38: 51.502741 | AM38: =$AF$26*E38^2+$AG$26*E38+$AH$26 -> 75.828396 | BG38: =$BC$5*E38^2+$BD$5*E38+$BE$5 -> 2.2988706
